Workbook
Name Власна_часова_шкала_дата: #N/A
Name Роздільник_категорія1: #N/A
Name Роздільник_область: #N/A
Name Роздільник_рік1: #N/A

Sheet Інтерактивна таблиця
B2: Рік | C2: <>0
B3: Категорія | C3: Товари для дому
D7: 1 | E7: 2 | F7: 3 | I7: 4 | J7: 5 | K7: 6 | N7: 7 | O7: 8 | P7: 9 | S7: 10 | T7: 11 | U7: 12
B8: Область | C8: Менеджер | D8: січ | E8: лют | F8: бер | G8: =IF($C$2="<>0","Всього 1 кв.",CONCATENATE($C$2," 1 кв. ")) -> Всього 1 кв. | I8: кві | J8: тра | K8: чер | L8: =IF($C$2="<>0","Всього 2 кв.",CONCATENATE($C$2," 2 кв. ")) -> Всього 2 кв. | N8: лип | O8: сер | P8: вер | Q8: =IF($C$2="<>0","Всього 3 кв.",CONCATENATE($C$2," 3 кв. ")) -> Всього 3 кв. | S8: жов | T8: лис | U8: гру | V8: =IF($C$2="<>0","Всього 4 кв.",CONCATENATE($C$2," 4 кв. ")) -> Всього 4 кв. | Y8: Total | Z8: Частка
B10: Total | D10: =SUM(D12,D15,D18,D23,D26) -> 251178 | E10: =SUM(E12,E15,E18,E23,E26) -> 238428 | F10: =SUM(F12,F15,F18,F23,F26) -> 247494 | H10: =SUM(D10:F10) -> 737100 | I10: =SUM(I12,I15,I18,I23,I26) -> 241950 | J10: =SUM(J12,J15,J18,J23,J26) -> 257316 | K10: =SUM(K12,K15,K18,K23,K26) -> 236822 | M10: =SUM(I10:K10) -> 736088 | N10: =SUM(N12,N15,N18,N23,N26) -> 234945 | O10: =SUM(O12,O15,O18,O23,O26) -> 242437 | P10: =SUM(P12,P15,P18,P23,P26) -> 235247 | R10: =SUM(N10:P10) -> 712629 | S10: =SUM(S12,S15,S18,S23,S26) -> 237397 | T10: =SUM(T12,T15,T18,T23,T26) -> 238499 | U10: =SUM(U12,U15,U18,U23,U26) -> 248324 | W10: =SUM(S10:U10) -> 724220 | Y10: =SUM(H10,M10,R10,W10) -> 2910037
B12: Житомирська | D12: =SUM(D13:D14) -> 42920 | E12: =SUM(E13:E14) -> 38814 | F12: =SUM(F13:F14) -> 41331 | H12: =SUM(D12:F12) -> 123065 | I12: =SUM(I13:I14) -> 38687 | J12: =SUM(J13:J14) -> 41513 | K12: =SUM(K13:K14) -> 41467 | M12: =SUM(I12:K12) -> 121667 | N12: =SUM(N13:N14) -> 38630 | O12: =SUM(O13:O14) -> 41649 | P12: =SUM(P13:P14) -> 38007 | R12: =SUM(N12:P12) -> 118286 | S12: =SUM(S13:S14) -> 42035 | T12: =SUM(T13:T14) -> 40507 | U12: =SUM(U13:U14) -> 38840 | W12: =SUM(S12:U12) -> 121382 | Y12: =SUM(H12,M12,R12,W12) -> 484400
C13: Коваль Дмитро | D13: =SUMIFS( тех!$J:$J, тех!$G:$G,'Інтерактивна таблиця'!$C$2, тех!$H:$H,'Інтерактивна таблиця'!D$7, тех!$E:$E,'Інтерактивна таблиця'!$C$3, тех!$B:$B,'Інтерактивна таблиця'!$B$12, тех!$D:$D,'Інтерактивна таблиця'!$C13 ) -> 20632 | E13: =SUMIFS( тех!$J:$J, тех!$G:$G,'Інтерактивна таблиця'!$C$2, тех!$H:$H,'Інтерактивна таблиця'!E$7, тех!$E:$E,'Інтерактивна таблиця'!$C$3, тех!$B:$B,'Інтерактивна таблиця'!$B$12, тех!$D:$D,'Інтерактивна таблиця'!$C13 ) -> 17918 | F13: =SUMIFS( тех!$J:$J, тех!$G:$G,'Інтерактивна таблиця'!$C$2, тех!$H:$H,'Інтерактивна таблиця'!F$7, тех!$E:$E,'Інтерактивна таблиця'!$C$3, тех!$B:$B,'Інтерактивна таблиця'!$B$12, тех!$D:$D,'Інтерактивна таблиця'!$C13 ) -> 20003 | H13: =SUM(D13:F13) -> 58553 | I13: =SUMIFS( тех!$J:$J, тех!$G:$G,'Інтерактивна таблиця'!$C$2, тех!$H:$H,'Інтерактивна таблиця'!I$7, тех!$E:$E,'Інтерактивна таблиця'!$C$3, тех!$B:$B,'Інтерактивна таблиця'!$B$12, тех!$D:$D,'Інтерактивна таблиця'!$C13 ) -> 20646 | J13: =SUMIFS( тех!$J:$J, тех!$G:$G,'Інтерактивна таблиця'!$C$2, тех!$H:$H,'Інтерактивна таблиця'!J$7, тех!$E:$E,'Інтерактивна таблиця'!$C$3, тех!$B:$B,'Інтерактивна таблиця'!$B$12, тех!$D:$D,'Інтерактивна таблиця'!$C13 ) -> 21845 | K13: =SUMIFS( тех!$J:$J, тех!$G:$G,'Інтерактивна таблиця'!$C$2, тех!$H:$H,'Інтерактивна таблиця'!K$7, тех!$E:$E,'Інтерактивна таблиця'!$C$3, тех!$B:$B,'Інтерактивна таблиця'!$B$12, тех!$D:$D,'Інтерактивна таблиця'!$C13 ) -> 19672 | M13: =SUM(I13:K13) -> 62163 | N13: =SUMIFS( тех!$J:$J, тех!$G:$G,'Інтерактивна таблиця'!$C$2, тех!$H:$H,'Інтерактивна таблиця'!N$7, тех!$E:$E,'Інтерактивна таблиця'!$C$3, тех!$B:$B,'Інтерактивна таблиця'!$B$12, тех!$D:$D,'Інтерактивна таблиця'!$C13 ) -> 19837 | O13: =SUMIFS( тех!$J:$J, тех!$G:$G,'Інтерактивна таблиця'!$C$2, тех!$H:$H,'Інтерактивна таблиця'!O$7, тех!$E:$E,'Інтерактивна таблиця'!$C$3, тех!$B:$B,'Інтерактивна таблиця'!$B$12, тех!$D:$D,'Інтерактивна таблиця'!$C13 ) -> 21263 | P13: =SUMIFS( тех!$J:$J, тех!$G:$G,'Інтерактивна таблиця'!$C$2, тех!$H:$H,'Інтерактивна таблиця'!P$7, тех!$E:$E,'Інтерактивна таблиця'!$C$3, тех!$B:$B,'Інтерактивна таблиця'!$B$12, тех!$D:$D,'Інтерактивна таблиця'!$C13 ) -> 19961 | R13: =SUM(N13:P13) -> 61061 | S13: =SUMIFS( тех!$J:$J, тех!$G:$G,'Інтерактивна таблиця'!$C$2, тех!$H:$H,'Інтерактивна таблиця'!S$7, тех!$E:$E,'Інтерактивна таблиця'!$C$3, тех!$B:$B,'Інтерактивна таблиця'!$B$12, тех!$D:$D,'Інтерактивна таблиця'!$C13 ) -> 20454 | T13: =SUMIFS( тех!$J:$J, тех!$G:$G,'Інтерактивна таблиця'!$C$2, тех!$H:$H,'Інтерактивна таблиця'!T$7, тех!$E:$E,'Інтерактивна таблиця'!$C$3, тех!$B:$B,'Інтерактивна таблиця'!$B$12, тех!$D:$D,'Інтерактивна таблиця'!$C13 ) -> 20479 | U13: =SUMIFS( тех!$J:$J, тех!$G:$G,'Інтерактивна таблиця'!$C$2, тех!$H:$H,'Інтерактивна таблиця'!U$7, тех!$E:$E,'Інтерактивна таблиця'!$C$3, тех!$B:$B,'Інтерактивна таблиця'!$B$12, тех!$D:$D,'Інтерактивна таблиця'!$C13 ) -> 19274 | W13: =SUM(S13:U13) -> 60207 | Y13: =SUM(H13,M13,R13,W13) -> 241984 | Z13: =Y13/$Y$10 -> 0.083154956
C14: Степанов Денис | D14: =SUMIFS( тех!$J:$J, тех!$G:$G,'Інтерактивна таблиця'!$C$2, тех!$H:$H,'Інтерактивна таблиця'!D$7, тех!$E:$E,'Інтерактивна таблиця'!$C$3, тех!$B:$B,'Інтерактивна таблиця'!$B$12, тех!$D:$D,'Інтерактивна таблиця'!$C14 ) -> 22288 | E14: =SUMIFS( тех!$J:$J, тех!$G:$G,'Інтерактивна таблиця'!$C$2, тех!$H:$H,'Інтерактивна таблиця'!E$7, тех!$E:$E,'Інтерактивна таблиця'!$C$3, тех!$B:$B,'Інтерактивна таблиця'!$B$12, тех!$D:$D,'Інтерактивна таблиця'!$C14 ) -> 20896 | F14: =SUMIFS( тех!$J:$J, тех!$G:$G,'Інтерактивна таблиця'!$C$2, тех!$H:$H,'Інтерактивна таблиця'!F$7, тех!$E:$E,'Інтерактивна таблиця'!$C$3, тех!$B:$B,'Інтерактивна таблиця'!$B$12, тех!$D:$D,'Інтерактивна таблиця'!$C14 ) -> 21328 | H14: =SUM(D14:F14) -> 64512 | I14: =SUMIFS( тех!$J:$J, тех!$G:$G,'Інтерактивна таблиця'!$C$2, тех!$H:$H,'Інтерактивна таблиця'!I$7, тех!$E:$E,'Інтерактивна таблиця'!$C$3, тех!$B:$B,'Інтерактивна таблиця'!$B$12, тех!$D:$D,'Інтерактивна таблиця'!$C14 ) -> 18041 | J14: =SUMIFS( тех!$J:$J, тех!$G:$G,'Інтерактивна таблиця'!$C$2, тех!$H:$H,'Інтерактивна таблиця'!J$7, тех!$E:$E,'Інтерактивна таблиця'!$C$3, тех!$B:$B,'Інтерактивна таблиця'!$B$12, тех!$D:$D,'Інтерактивна таблиця'!$C14 ) -> 19668 | K14: =SUMIFS( тех!$J:$J, тех!$G:$G,'Інтерактивна таблиця'!$C$2, тех!$H:$H,'Інтерактивна таблиця'!K$7, тех!$E:$E,'Інтерактивна таблиця'!$C$3, тех!$B:$B,'Інтерактивна таблиця'!$B$12, тех!$D:$D,'Інтерактивна таблиця'!$C14 ) -> 21795 | M14: =SUM(I14:K14) -> 59504 | N14: =SUMIFS( тех!$J:$J, тех!$G:$G,'Інтерактивна таблиця'!$C$2, тех!$H:$H,'Інтерактивна таблиця'!N$7, тех!$E:$E,'Інтерактивна таблиця'!$C$3, тех!$B:$B,'Інтерактивна таблиця'!$B$12, тех!$D:$D,'Інтерактивна таблиця'!$C14 ) -> 18793 | O14: =SUMIFS( тех!$J:$J, тех!$G:$G,'Інтерактивна таблиця'!$C$2, тех!$H:$H,'Інтерактивна таблиця'!O$7, тех!$E:$E,'Інтерактивна таблиця'!$C$3, тех!$B:$B,'Інтерактивна таблиця'!$B$12, тех!$D:$D,'Інтерактивна таблиця'!$C14 ) -> 20386 | P14: =SUMIFS( тех!$J:$J, тех!$G:$G,'Інтерактивна таблиця'!$C$2, тех!$H:$H,'Інтерактивна таблиця'!P$7, тех!$E:$E,'Інтерактивна таблиця'!$C$3, тех!$B:$B,'Інтерактивна таблиця'!$B$12, тех!$D:$D,'Інтерактивна таблиця'!$C14 ) -> 18046 | R14: =SUM(N14:P14) -> 57225 | S14: =SUMIFS( тех!$J:$J, тех!$G:$G,'Інтерактивна таблиця'!$C$2, тех!$H:$H,'Інтерактивна таблиця'!S$7, тех!$E:$E,'Інтерактивна таблиця'!$C$3, тех!$B:$B,'Інтерактивна таблиця'!$B$12, тех!$D:$D,'Інтерактивна таблиця'!$C14 ) -> 21581 | T14: =SUMIFS( тех!$J:$J, тех!$G:$G,'Інтерактивна таблиця'!$C$2, тех!$H:$H,'Інтерактивна таблиця'!T$7, тех!$E:$E,'Інтерактивна таблиця'!$C$3, тех!$B:$B,'Інтерактивна таблиця'!$B$12, тех!$D:$D,'Інтерактивна таблиця'!$C14 ) -> 20028 | U14: =SUMIFS( тех!$J:$J, тех!$G:$G,'Інтерактивна таблиця'!$C$2, тех!$H:$H,'Інтерактивна таблиця'!U$7, тех!$E:$E,'Інтерактивна таблиця'!$C$3, тех!$B:$B,'Інтерактивна таблиця'!$B$12, тех!$D:$D,'Інтерактивна таблиця'!$C14 ) -> 19566 | W14: =SUM(S14:U14) -> 61175 | Y14: =SUM(H14,M14,R14,W14) -> 242416 | Z14: =Y14/$Y$10 -> 0.083303408
B15: Запорізька | D15: =SUM(D16:D17) -> 42251 | E15: =SUM(E16:E17) -> 40075 | F15: =SUM(F16:F17) -> 40791 | H15: =SUM(D15:F15) -> 123117 | I15: =SUM(I16:I17) -> 38358 | J15: =SUM(J16:J17) -> 47696 | K15: =SUM(K16:K17) -> 35670 | M15: =SUM(I15:K15) -> 121724 | N15: =SUM(N16:N17) -> 39754 | O15: =SUM(O16:O17) -> 40648 | P15: =SUM(P16:P17) -> 35231 | R15: =SUM(N15:P15) -> 115633 | S15: =SUM(S16:S17) -> 38242 | T15: =SUM(T16:T17) -> 36864 | U15: =SUM(U16:U17) -> 42704 | W15: =SUM(S15:U15) -> 117810 | Y15: =SUM(H15,M15,R15,W15) -> 478284
C16: Пекар Максим | D16: =SUMIFS( тех!$J:$J, тех!$G:$G,'Інтерактивна таблиця'!$C$2, тех!$H:$H,'Інтерактивна таблиця'!D$7, тех!$E:$E,'Інтерактивна таблиця'!$C$3, тех!$B:$B,'Інтерактивна таблиця'!$B$15, тех!$D:$D,'Інтерактивна таблиця'!$C16 ) -> 20578 | E16: =SUMIFS( тех!$J:$J, тех!$G:$G,'Інтерактивна таблиця'!$C$2, тех!$H:$H,'Інтерактивна таблиця'!E$7, тех!$E:$E,'Інтерактивна таблиця'!$C$3, тех!$B:$B,'Інтерактивна таблиця'!$B$15, тех!$D:$D,'Інтерактивна таблиця'!$C16 ) -> 19764 | F16: =SUMIFS( тех!$J:$J, тех!$G:$G,'Інтерактивна таблиця'!$C$2, тех!$H:$H,'Інтерактивна таблиця'!F$7, тех!$E:$E,'Інтерактивна таблиця'!$C$3, тех!$B:$B,'Інтерактивна таблиця'!$B$15, тех!$D:$D,'Інтерактивна таблиця'!$C16 ) -> 20791 | H16: =SUM(D16:F16) -> 61133 | I16: =SUMIFS( тех!$J:$J, тех!$G:$G,'Інтерактивна таблиця'!$C$2, тех!$H:$H,'Інтерактивна таблиця'!I$7, тех!$E:$E,'Інтерактивна таблиця'!$C$3, тех!$B:$B,'Інтерактивна таблиця'!$B$15, тех!$D:$D,'Інтерактивна таблиця'!$C16 ) -> 18564 | J16: =SUMIFS( тех!$J:$J, тех!$G:$G,'Інтерактивна таблиця'!$C$2, тех!$H:$H,'Інтерактивна таблиця'!J$7, тех!$E:$E,'Інтерактивна таблиця'!$C$3, тех!$B:$B,'Інтерактивна таблиця'!$B$15, тех!$D:$D,'Інтерактивна таблиця'!$C16 ) -> 24110 | K16: =SUMIFS( тех!$J:$J, тех!$G:$G,'Інтерактивна таблиця'!$C$2, тех!$H:$H,'Інтерактивна таблиця'!K$7, тех!$E:$E,'Інтерактивна таблиця'!$C$3, тех!$B:$B,'Інтерактивна таблиця'!$B$15, тех!$D:$D,'Інтерактивна таблиця'!$C16 ) -> 18666 | M16: =SUM(I16:K16) -> 61340 | N16: =SUMIFS( тех!$J:$J, тех!$G:$G,'Інтерактивна таблиця'!$C$2, тех!$H:$H,'Інтерактивна таблиця'!N$7, тех!$E:$E,'Інтерактивна таблиця'!$C$3, тех!$B:$B,'Інтерактивна таблиця'!$B$15, тех!$D:$D,'Інтерактивна таблиця'!$C16 ) -> 19710 | O16: =SUMIFS( тех!$J:$J, тех!$G:$G,'Інтерактивна таблиця'!$C$2, тех!$H:$H,'Інтерактивна таблиця'!O$7, тех!$E:$E,'Інтерактивна таблиця'!$C$3, тех!$B:$B,'Інтерактивна таблиця'!$B$15, тех!$D:$D,'Інтерактивна таблиця'!$C16 ) -> 21535 | P16: =SUMIFS( тех!$J:$J, тех!$G:$G,'Інтерактивна таблиця'!$C$2, тех!$H:$H,'Інтерактивна таблиця'!P$7, тех!$E:$E,'Інтерактивна таблиця'!$C$3, тех!$B:$B,'Інтерактивна таблиця'!$B$15, тех!$D:$D,'Інтерактивна таблиця'!$C16 ) -> 15686 | R16: =SUM(N16:P16) -> 56931 | S16: =SUMIFS( тех!$J:$J, тех!$G:$G,'Інтерактивна таблиця'!$C$2, тех!$H:$H,'Інтерактивна таблиця'!S$7, тех!$E:$E,'Інтерактивна таблиця'!$C$3, тех!$B:$B,'Інтерактивна таблиця'!$B$15, тех!$D:$D,'Інтерактивна таблиця'!$C16 ) -> 19603 | T16: =SUMIFS( тех!$J:$J, тех!$G:$G,'Інтерактивна таблиця'!$C$2, тех!$H:$H,'Інтерактивна таблиця'!T$7, тех!$E:$E,'Інтерактивна таблиця'!$C$3, тех!$B:$B,'Інтерактивна таблиця'!$B$15, тех!$D:$D,'Інтерактивна таблиця'!$C16 ) -> 17323 | U16: =SUMIFS( тех!$J:$J, тех!$G:$G,'Інтерактивна таблиця'!$C$2, тех!$H:$H,'Інтерактивна таблиця'!U$7, тех!$E:$E,'Інтерактивна таблиця'!$C$3, тех!$B:$B,'Інтерактивна таблиця'!$B$15, тех!$D:$D,'Інтерактивна таблиця'!$C16 ) -> 21111 | W16: =SUM(S16:U16) -> 58037 | Y16: =SUM(H16,M16,R16,W16) -> 237441 | Z16: =Y16/$Y$10 -> 0.081593808
C17: Сидоров Дмитро | D17: =SUMIFS( тех!$J:$J, тех!$G:$G,'Інтерактивна таблиця'!$C$2, тех!$H:$H,'Інтерактивна таблиця'!D$7, тех!$E:$E,'Інтерактивна таблиця'!$C$3, тех!$B:$B,'Інтерактивна таблиця'!$B$15, тех!$D:$D,'Інтерактивна таблиця'!$C17 ) -> 21673 | E17: =SUMIFS( тех!$J:$J, тех!$G:$G,'Інтерактивна таблиця'!$C$2, тех!$H:$H,'Інтерактивна таблиця'!E$7, тех!$E:$E,'Інтерактивна таблиця'!$C$3, тех!$B:$B,'Інтерактивна таблиця'!$B$15, тех!$D:$D,'Інтерактивна таблиця'!$C17 ) -> 20311 | F17: =SUMIFS( тех!$J:$J, тех!$G:$G,'Інтерактивна таблиця'!$C$2, тех!$H:$H,'Інтерактивна таблиця'!F$7, тех!$E:$E,'Інтерактивна таблиця'!$C$3, тех!$B:$B,'Інтерактивна таблиця'!$B$15, тех!$D:$D,'Інтерактивна таблиця'!$C17 ) -> 20000 | H17: =SUM(D17:F17) -> 61984 | I17: =SUMIFS( тех!$J:$J, тех!$G:$G,'Інтерактивна таблиця'!$C$2, тех!$H:$H,'Інтерактивна таблиця'!I$7, тех!$E:$E,'Інтерактивна таблиця'!$C$3, тех!$B:$B,'Інтерактивна таблиця'!$B$15, тех!$D:$D,'Інтерактивна таблиця'!$C17 ) -> 19794 | J17: =SUMIFS( тех!$J:$J, тех!$G:$G,'Інтерактивна таблиця'!$C$2, тех!$H:$H,'Інтерактивна таблиця'!J$7, тех!$E:$E,'Інтерактивна таблиця'!$C$3, тех!$B:$B,'Інтерактивна таблиця'!$B$15, тех!$D:$D,'Інтерактивна таблиця'!$C17 ) -> 23586 | K17: =SUMIFS( тех!$J:$J, тех!$G:$G,'Інтерактивна таблиця'!$C$2, тех!$H:$H,'Інтерактивна таблиця'!K$7, тех!$E:$E,'Інтерактивна таблиця'!$C$3, тех!$B:$B,'Інтерактивна таблиця'!$B$15, тех!$D:$D,'Інтерактивна таблиця'!$C17 ) -> 17004 | M17: =SUM(I17:K17) -> 60384 | N17: =SUMIFS( тех!$J:$J, тех!$G:$G,'Інтерактивна таблиця'!$C$2, тех!$H:$H,'Інтерактивна таблиця'!N$7, тех!$E:$E,'Інтерактивна таблиця'!$C$3, тех!$B:$B,'Інтерактивна таблиця'!$B$15, тех!$D:$D,'Інтерактивна таблиця'!$C17 ) -> 20044 | O17: =SUMIFS( тех!$J:$J, тех!$G:$G,'Інтерактивна таблиця'!$C$2, тех!$H:$H,'Інтерактивна таблиця'!O$7, тех!$E:$E,'Інтерактивна таблиця'!$C$3, тех!$B:$B,'Інтерактивна таблиця'!$B$15, тех!$D:$D,'Інтерактивна таблиця'!$C17 ) -> 19113 | P17: =SUMIFS( тех!$J:$J, тех!$G:$G,'Інтерактивна таблиця'!$C$2, тех!$H:$H,'Інтерактивна таблиця'!P$7, тех!$E:$E,'Інтерактивна таблиця'!$C$3, тех!$B:$B,'Інтерактивна таблиця'!$B$15, тех!$D:$D,'Інтерактивна таблиця'!$C17 ) -> 19545 | R17: =SUM(N17:P17) -> 58702 | S17: =SUMIFS( тех!$J:$J, тех!$G:$G,'Інтерактивна таблиця'!$C$2, тех!$H:$H,'Інтерактивна таблиця'!S$7, тех!$E:$E,'Інтерактивна таблиця'!$C$3, тех!$B:$B,'Інтерактивна таблиця'!$B$15, тех!$D:$D,'Інтерактивна таблиця'!$C17 ) -> 18639 | T17: =SUMIFS( тех!$J:$J, тех!$G:$G,'Інтерактивна таблиця'!$C$2, тех!$H:$H,'Інтерактивна таблиця'!T$7, тех!$E:$E,'Інтерактивна таблиця'!$C$3, тех!$B:$B,'Інтерактивна таблиця'!$B$15, тех!$D:$D,'Інтерактивна таблиця'!$C17 ) -> 19541 | U17: =SUMIFS( тех!$J:$J, тех!$G:$G,'Інтерактивна таблиця'!$C$2, тех!$H:$H,'Інтерактивна таблиця'!U$7, тех!$E:$E,'Інтерактивна таблиця'!$C$3, тех!$B:$B,'Інтерактивна таблиця'!$B$15, тех!$D:$D,'Інтерактивна таблиця'!$C17 ) -> 21593 | W17: =SUM(S17:U17) -> 59773 | Y17: =SUM(H17,M17,R17,W17) -> 240843 | Z17: =Y17/$Y$10 -> 0.082762865
B18: Київська | D18: =SUM(D19:D22) -> 80284 | E18: =SUM(E19:E22) -> 79319 | F18: =SUM(F19:F22) -> 85911 | H18: =SUM(D18:F18) -> 245514 | I18: =SUM(I19:I22) -> 80344 | J18: =SUM(J19:J22) -> 78678 | K18: =SUM(K19:K22) -> 79295 | M18: =SUM(I18:K18) -> 238317 | N18: =SUM(N19:N22) -> 75508 | O18: =SUM(O19:O22) -> 75355 | P18: =SUM(P19:P22) -> 80215 | R18: =SUM(N18:P18) -> 231078 | S18: =SUM(S19:S22) -> 82433 | T18: =SUM(T19:T22) -> 82528 | U18: =SUM(U19:U22) -> 85088 | W18: =SUM(S18:U18) -> 250049 | Y18: =SUM(H18,M18,R18,W18) -> 964958
C19: Шевченко Юрій | D19: =SUMIFS( тех!$J:$J, тех!$G:$G,'Інтерактивна таблиця'!$C$2, тех!$H:$H,'Інтерактивна таблиця'!D$7, тех!$E:$E,'Інтерактивна таблиця'!$C$3, тех!$B:$B,'Інтерактивна таблиця'!$B$18, тех!$D:$D,'Інтерактивна таблиця'!$C19 ) -> 21181 | E19: =SUMIFS( тех!$J:$J, тех!$G:$G,'Інтерактивна таблиця'!$C$2, тех!$H:$H,'Інтерактивна таблиця'!E$7, тех!$E:$E,'Інтерактивна таблиця'!$C$3, тех!$B:$B,'Інтерактивна таблиця'!$B$18, тех!$D:$D,'Інтерактивна таблиця'!$C19 ) -> 17853 | F19: =SUMIFS( тех!$J:$J, тех!$G:$G,'Інтерактивна таблиця'!$C$2, тех!$H:$H,'Інтерактивна таблиця'!F$7, тех!$E:$E,'Інтерактивна таблиця'!$C$3, тех!$B:$B,'Інтерактивна таблиця'!$B$18, тех!$D:$D,'Інтерактивна таблиця'!$C19 ) -> 21235 | H19: =SUM(D19:F19) -> 60269 | I19: =SUMIFS( тех!$J:$J, тех!$G:$G,'Інтерактивна таблиця'!$C$2, тех!$H:$H,'Інтерактивна таблиця'!I$7, тех!$E:$E,'Інтерактивна таблиця'!$C$3, тех!$B:$B,'Інтерактивна таблиця'!$B$18, тех!$D:$D,'Інтерактивна таблиця'!$C19 ) -> 18630 | J19: =SUMIFS( тех!$J:$J, тех!$G:$G,'Інтерактивна таблиця'!$C$2, тех!$H:$H,'Інтерактивна таблиця'!J$7, тех!$E:$E,'Інтерактивна таблиця'!$C$3, тех!$B:$B,'Інтерактивна таблиця'!$B$18, тех!$D:$D,'Інтерактивна таблиця'!$C19 ) -> 19332 | K19: =SUMIFS( тех!$J:$J, тех!$G:$G,'Інтерактивна таблиця'!$C$2, тех!$H:$H,'Інтерактивна таблиця'!K$7, тех!$E:$E,'Інтерактивна таблиця'!$C$3, тех!$B:$B,'Інтерактивна таблиця'!$B$18, тех!$D:$D,'Інтерактивна таблиця'!$C19 ) -> 20671 | M19: =SUM(I19:K19) -> 58633 | N19: =SUMIFS( тех!$J:$J, тех!$G:$G,'Інтерактивна таблиця'!$C$2, тех!$H:$H,'Інтерактивна таблиця'!N$7, тех!$E:$E,'Інтерактивна таблиця'!$C$3, тех!$B:$B,'Інтерактивна таблиця'!$B$18, тех!$D:$D,'Інтерактивна таблиця'!$C19 ) -> 21741 | O19: =SUMIFS( тех!$J:$J, тех!$G:$G,'Інтерактивна таблиця'!$C$2, тех!$H:$H,'Інтерактивна таблиця'!O$7, тех!$E:$E,'Інтерактивна таблиця'!$C$3, тех!$B:$B,'Інтерактивна таблиця'!$B$18, тех!$D:$D,'Інтерактивна таблиця'!$C19 ) -> 20874 | P19: =SUMIFS( тех!$J:$J, тех!$G:$G,'Інтерактивна таблиця'!$C$2, тех!$H:$H,'Інтерактивна таблиця'!P$7, тех!$E:$E,'Інтерактивна таблиця'!$C$3, тех!$B:$B,'Інтерактивна таблиця'!$B$18, тех!$D:$D,'Інтерактивна таблиця'!$C19 ) -> 18208 | R19: =SUM(N19:P19) -> 60823 | S19: =SUMIFS( тех!$J:$J, тех!$G:$G,'Інтерактивна таблиця'!$C$2, тех!$H:$H,'Інтерактивна таблиця'!S$7, тех!$E:$E,'Інтерактивна таблиця'!$C$3, тех!$B:$B,'Інтерактивна таблиця'!$B$18, тех!$D:$D,'Інтерактивна таблиця'!$C19 ) -> 22111 | T19: =SUMIFS( тех!$J:$J, тех!$G:$G,'Інтерактивна таблиця'!$C$2, тех!$H:$H,'Інтерактивна таблиця'!T$7, тех!$E:$E,'Інтерактивна таблиця'!$C$3, тех!$B:$B,'Інтерактивна таблиця'!$B$18, тех!$D:$D,'Інтерактивна таблиця'!$C19 ) -> 19011 | U19: =SUMIFS( тех!$J:$J, тех!$G:$G,'Інтерактивна таблиця'!$C$2, тех!$H:$H,'Інтерактивна таблиця'!U$7, тех!$E:$E,'Інтерактивна таблиця'!$C$3, тех!$B:$B,'Інтерактивна таблиця'!$B$18, тех!$D:$D,'Інтерактивна таблиця'!$C19 ) -> 21254 | W19: =SUM(S19:U19) -> 62376 | Y19: =SUM(H19,M19,R19,W19) -> 242101 | Z19: =Y19/$Y$10 -> 0.083195162
C20: Колесник Анастасія | D20: =SUMIFS( тех!$J:$J, тех!$G:$G,'Інтерактивна таблиця'!$C$2, тех!$H:$H,'Інтерактивна таблиця'!D$7, тех!$E:$E,'Інтерактивна таблиця'!$C$3, тех!$B:$B,'Інтерактивна таблиця'!$B$18, тех!$D:$D,'Інтерактивна таблиця'!$C20 ) -> 19256 | E20: =SUMIFS( тех!$J:$J, тех!$G:$G,'Інтерактивна таблиця'!$C$2, тех!$H:$H,'Інтерактивна таблиця'!E$7, тех!$E:$E,'Інтерактивна таблиця'!$C$3, тех!$B:$B,'Інтерактивна таблиця'!$B$18, тех!$D:$D,'Інтерактивна таблиця'!$C20 ) -> 21998 | F20: =SUMIFS( тех!$J:$J, тех!$G:$G,'Інтерактивна таблиця'!$C$2, тех!$H:$H,'Інтерактивна таблиця'!F$7, тех!$E:$E,'Інтерактивна таблиця'!$C$3, тех!$B:$B,'Інтерактивна таблиця'!$B$18, тех!$D:$D,'Інтерактивна таблиця'!$C20 ) -> 22923 | H20: =SUM(D20:F20) -> 64177 | I20: =SUMIFS( тех!$J:$J, тех!$G:$G,'Інтерактивна таблиця'!$C$2, тех!$H:$H,'Інтерактивна таблиця'!I$7, тех!$E:$E,'Інтерактивна таблиця'!$C$3, тех!$B:$B,'Інтерактивна таблиця'!$B$18, тех!$D:$D,'Інтерактивна таблиця'!$C20 ) -> 21800 | J20: =SUMIFS( тех!$J:$J, тех!$G:$G,'Інтерактивна таблиця'!$C$2, тех!$H:$H,'Інтерактивна таблиця'!J$7, тех!$E:$E,'Інтерактивна таблиця'!$C$3, тех!$B:$B,'Інтерактивна таблиця'!$B$18, тех!$D:$D,'Інтерактивна таблиця'!$C20 ) -> 18354 | K20: =SUMIFS( тех!$J:$J, тех!$G:$G,'Інтерактивна таблиця'!$C$2, тех!$H:$H,'Інтерактивна таблиця'!K$7, тех!$E:$E,'Інтерактивна таблиця'!$C$3, тех!$B:$B,'Інтерактивна таблиця'!$B$18, тех!$D:$D,'Інтерактивна таблиця'!$C20 ) -> 19345 | M20: =SUM(I20:K20) -> 59499 | N20: =SUMIFS( тех!$J:$J, тех!$G:$G,'Інтерактивна таблиця'!$C$2, тех!$H:$H,'Інтерактивна таблиця'!N$7, тех!$E:$E,'Інтерактивна таблиця'!$C$3, тех!$B:$B,'Інтерактивна таблиця'!$B$18, тех!$D:$D,'Інтерактивна таблиця'!$C20 ) -> 17246 | O20: =SUMIFS( тех!$J:$J, тех!$G:$G,'Інтерактивна таблиця'!$C$2, тех!$H:$H,'Інтерактивна таблиця'!O$7, тех!$E:$E,'Інтерактивна таблиця'!$C$3, тех!$B:$B,'Інтерактивна таблиця'!$B$18, тех!$D:$D,'Інтерактивна таблиця'!$C20 ) -> 19504 | P20: =SUMIFS( тех!$J:$J, тех!$G:$G,'Інтерактивна таблиця'!$C$2, тех!$H:$H,'Інтерактивна таблиця'!P$7, тех!$E:$E,'Інтерактивна таблиця'!$C$3, тех!$B:$B,'Інтерактивна таблиця'!$B$18, тех!$D:$D,'Інтерактивна таблиця'!$C20 ) -> 19918 | R20: =SUM(N20:P20) -> 56668 | S20: =SUMIFS( тех!$J:$J, тех!$G:$G,'Інтерактивна таблиця'!$C$2, тех!$H:$H,'Інтерактивна таблиця'!S$7, тех!$E:$E,'Інтерактивна таблиця'!$C$3, тех!$B:$B,'Інтерактивна таблиця'!$B$18, тех!$D:$D,'Інтерактивна таблиця'!$C20 ) -> 18034 | T20: =SUMIFS( тех!$J:$J, тех!$G:$G,'Інтерактивна таблиця'!$C$2, тех!$H:$H,'Інтерактивна таблиця'!T$7, тех!$E:$E,'Інтерактивна таблиця'!$C$3, тех!$B:$B,'Інтерактивна таблиця'!$B$18, тех!$D:$D,'Інтерактивна таблиця'!$C20 ) -> 20885 | U20: =SUMIFS( тех!$J:$J, тех!$G:$G,'Інтерактивна таблиця'!$C$2, тех!$H:$H,'Інтерактивна таблиця'!U$7, тех!$E:$E,'Інтерактивна таблиця'!$C$3, тех!$B:$B,'Інтерактивна таблиця'!$B$18, тех!$D:$D,'Інтерактивна таблиця'!$C20 ) -> 20411 | W20: =SUM(S20:U20) -> 59330 | Y20: =SUM(H20,M20,R20,W20) -> 239674 | Z20: =Y20/$Y$10 -> 0.082361152
C21: Савич Андрій | D21: =SUMIFS( тех!$J:$J, тех!$G:$G,'Інтерактивна таблиця'!$C$2, тех!$H:$H,'Інтерактивна таблиця'!D$7, тех!$E:$E,'Інтерактивна таблиця'!$C$3, тех!$B:$B,'Інтерактивна таблиця'!$B$18, тех!$D:$D,'Інтерактивна таблиця'!$C21 ) -> 19800 | E21: =SUMIFS( тех!$J:$J, тех!$G:$G,'Інтерактивна таблиця'!$C$2, тех!$H:$H,'Інтерактивна таблиця'!E$7, тех!$E:$E,'Інтерактивна таблиця'!$C$3, тех!$B:$B,'Інтерактивна таблиця'!$B$18, тех!$D:$D,'Інтерактивна таблиця'!$C21 ) -> 18824 | F21: =SUMIFS( тех!$J:$J, тех!$G:$G,'Інтерактивна таблиця'!$C$2, тех!$H:$H,'Інтерактивна таблиця'!F$7, тех!$E:$E,'Інтерактивна таблиця'!$C$3, тех!$B:$B,'Інтерактивна таблиця'!$B$18, тех!$D:$D,'Інтерактивна таблиця'!$C21 ) -> 19069 | H21: =SUM(D21:F21) -> 57693 | I21: =SUMIFS( тех!$J:$J, тех!$G:$G,'Інтерактивна таблиця'!$C$2, тех!$H:$H,'Інтерактивна таблиця'!I$7, тех!$E:$E,'Інтерактивна таблиця'!$C$3, тех!$B:$B,'Інтерактивна таблиця'!$B$18, тех!$D:$D,'Інтерактивна таблиця'!$C21 ) -> 18966 | J21: =SUMIFS( тех!$J:$J, тех!$G:$G,'Інтерактивна таблиця'!$C$2, тех!$H:$H,'Інтерактивна таблиця'!J$7, тех!$E:$E,'Інтерактивна таблиця'!$C$3, тех!$B:$B,'Інтерактивна таблиця'!$B$18, тех!$D:$D,'Інтерактивна таблиця'!$C21 ) -> 21195 | K21: =SUMIFS( тех!$J:$J, тех!$G:$G,'Інтерактивна таблиця'!$C$2, тех!$H:$H,'Інтерактивна таблиця'!K$7, тех!$E:$E,'Інтерактивна таблиця'!$C$3, тех!$B:$B,'Інтерактивна таблиця'!$B$18, тех!$D:$D,'Інтерактивна таблиця'!$C21 ) -> 19293 | M21: =SUM(I21:K21) -> 59454 | N21: =SUMIFS( тех!$J:$J, тех!$G:$G,'Інтерактивна таблиця'!$C$2, тех!$H:$H,'Інтерактивна таблиця'!N$7, тех!$E:$E,'Інтерактивна таблиця'!$C$3, тех!$B:$B,'Інтерактивна таблиця'!$B$18, тех!$D:$D,'Інтерактивна таблиця'!$C21 ) -> 17434 | O21: =SUMIFS( тех!$J:$J, тех!$G:$G,'Інтерактивна таблиця'!$C$2, тех!$H:$H,'Інтерактивна таблиця'!O$7, тех!$E:$E,'Інтерактивна таблиця'!$C$3, тех!$B:$B,'Інтерактивна таблиця'!$B$18, тех!$D:$D,'Інтерактивна таблиця'!$C21 ) -> 17517 | P21: =SUMIFS( тех!$J:$J, тех!$G:$G,'Інтерактивна таблиця'!$C$2, тех!$H:$H,'Інтерактивна таблиця'!P$7, тех!$E:$E,'Інтерактивна таблиця'!$C$3, тех!$B:$B,'Інтерактивна таблиця'!$B$18, тех!$D:$D,'Інтерактивна таблиця'!$C21 ) -> 21282 | R21: =SUM(N21:P21) -> 56233 | S21: =SUMIFS( тех!$J:$J, тех!$G:$G,'Інтерактивна таблиця'!$C$2, тех!$H:$H,'Інтерактивна таблиця'!S$7, тех!$E:$E,'Інтерактивна таблиця'!$C$3, тех!$B:$B,'Інтерактивна таблиця'!$B$18, тех!$D:$D,'Інтерактивна таблиця'!$C21 ) -> 19767 | T21: =SUMIFS( тех!$J:$J, тех!$G:$G,'Інтерактивна таблиця'!$C$2, тех!$H:$H,'Інтерактивна таблиця'!T$7, тех!$E:$E,'Інтерактивна таблиця'!$C$3, тех!$B:$B,'Інтерактивна таблиця'!$B$18, тех!$D:$D,'Інтерактивна таблиця'!$C21 ) -> 21604 | U21: =SUMIFS( тех!$J:$J, тех!$G:$G,'Інтерактивна таблиця'!$C$2, тех!$H:$H,'Інтерактивна таблиця'!U$7, тех!$E:$E,'Інтерактивна таблиця'!$C$3, тех!$B:$B,'Інтерактивна таблиця'!$B$18, тех!$D:$D,'Інтерактивна таблиця'!$C21 ) -> 20159 | W21: =SUM(S21:U21) -> 61530 | Y21: =SUM(H21,M21,R21,W21) -> 234910 | Z21: =Y21/$Y$10 -> 0.08072406
C22: Іванов Іван | D22: =SUMIFS( тех!$J:$J, тех!$G:$G,'Інтерактивна таблиця'!$C$2, тех!$H:$H,'Інтерактивна таблиця'!D$7, тех!$E:$E,'Інтерактивна таблиця'!$C$3, тех!$B:$B,'Інтерактивна таблиця'!$B$18, тех!$D:$D,'Інтерактивна таблиця'!$C22 ) -> 20047 | E22: =SUMIFS( тех!$J:$J, тех!$G:$G,'Інтерактивна таблиця'!$C$2, тех!$H:$H,'Інтерактивна таблиця'!E$7, тех!$E:$E,'Інтерактивна таблиця'!$C$3, тех!$B:$B,'Інтерактивна таблиця'!$B$18, тех!$D:$D,'Інтерактивна таблиця'!$C22 ) -> 20644 | F22: =SUMIFS( тех!$J:$J, тех!$G:$G,'Інтерактивна таблиця'!$C$2, тех!$H:$H,'Інтерактивна таблиця'!F$7, тех!$E:$E,'Інтерактивна таблиця'!$C$3, тех!$B:$B,'Інтерактивна таблиця'!$B$18, тех!$D:$D,'Інтерактивна таблиця'!$C22 ) -> 22684 | H22: =SUM(D22:F22) -> 63375 | I22: =SUMIFS( тех!$J:$J, тех!$G:$G,'Інтерактивна таблиця'!$C$2, тех!$H:$H,'Інтерактивна таблиця'!I$7, тех!$E:$E,'Інтерактивна таблиця'!$C$3, тех!$B:$B,'Інтерактивна таблиця'!$B$18, тех!$D:$D,'Інтерактивна таблиця'!$C22 ) -> 20948 | J22: =SUMIFS( тех!$J:$J, тех!$G:$G,'Інтерактивна таблиця'!$C$2, тех!$H:$H,'Інтерактивна таблиця'!J$7, тех!$E:$E,'Інтерактивна таблиця'!$C$3, тех!$B:$B,'Інтерактивна таблиця'!$B$18, тех!$D:$D,'Інтерактивна таблиця'!$C22 ) -> 19797 | K22: =SUMIFS( тех!$J:$J, тех!$G:$G,'Інтерактивна таблиця'!$C$2, тех!$H:$H,'Інтерактивна таблиця'!K$7, тех!$E:$E,'Інтерактивна таблиця'!$C$3, тех!$B:$B,'Інтерактивна таблиця'!$B$18, тех!$D:$D,'Інтерактивна таблиця'!$C22 ) -> 19986 | M22: =SUM(I22:K22) -> 60731 | N22: =SUMIFS( тех!$J:$J, тех!$G:$G,'Інтерактивна таблиця'!$C$2, тех!$H:$H,'Інтерактивна таблиця'!N$7, тех!$E:$E,'Інтерактивна таблиця'!$C$3, тех!$B:$B,'Інтерактивна таблиця'!$B$18, тех!$D:$D,'Інтерактивна таблиця'!$C22 ) -> 19087 | O22: =SUMIFS( тех!$J:$J, тех!$G:$G,'Інтерактивна таблиця'!$C$2, тех!$H:$H,'Інтерактивна таблиця'!O$7, тех!$E:$E,'Інтерактивна таблиця'!$C$3, тех!$B:$B,'Інтерактивна таблиця'!$B$18, тех!$D:$D,'Інтерактивна таблиця'!$C22 ) -> 17460 | P22: =SUMIFS( тех!$J:$J, тех!$G:$G,'Інтерактивна таблиця'!$C$2, тех!$H:$H,'Інтерактивна таблиця'!P$7, тех!$E:$E,'Інтерактивна таблиця'!$C$3, тех!$B:$B,'Інтерактивна таблиця'!$B$18, тех!$D:$D,'Інтерактивна таблиця'!$C22 ) -> 20807 | R22: =SUM(N22:P22) -> 57354 | S22: =SUMIFS( тех!$J:$J, тех!$G:$G,'Інтерактивна таблиця'!$C$2, тех!$H:$H,'Інтерактивна таблиця'!S$7, тех!$E:$E,'Інтерактивна таблиця'!$C$3, тех!$B:$B,'Інтерактивна таблиця'!$B$18, тех!$D:$D,'Інтерактивна таблиця'!$C22 ) -> 22521 | T22: =SUMIFS( тех!$J:$J, тех!$G:$G,'Інтерактивна таблиця'!$C$2, тех!$H:$H,'Інтерактивна таблиця'!T$7, тех!$E:$E,'Інтерактивна таблиця'!$C$3, тех!$B:$B,'Інтерактивна таблиця'!$B$18, тех!$D:$D,'Інтерактивна таблиця'!$C22 ) -> 21028 | U22: =SUMIFS( тех!$J:$J, тех!$G:$G,'Інтерактивна таблиця'!$C$2, тех!$H:$H,'Інтерактивна таблиця'!U$7, тех!$E:$E,'Інтерактивна таблиця'!$C$3, тех!$B:$B,'Інтерактивна таблиця'!$B$18, тех!$D:$D,'Інтерактивна таблиця'!$C22 ) -> 23264 | W22: =SUM(S22:U22) -> 66813 | Y22: =SUM(H22,M22,R22,W22) -> 248273 | Z22: =Y22/$Y$10 -> 0.085316097
B23: Одеська | D23: =SUM(D24:D25) -> 40846 | E23: =SUM(E24:E25) -> 41474 | F23: =SUM(F24:F25) -> 38392 | H23: =SUM(D23:F23) -> 120712 | I23: =SUM(I24:I25) -> 42445 | J23: =SUM(J24:J25) -> 43317 | K23: =SUM(K24:K25) -> 40210 | M23: =SUM(I23:K23) -> 125972 | N23: =SUM(N24:N25) -> 39434 | O23: =SUM(O24:O25) -> 44247 | P23: =SUM(P24:P25) -> 41464 | R23: =SUM(N23:P23) -> 125145 | S23: =SUM(S24:S25) -> 36645 | T23: =SUM(T24:T25) -> 38030 | U23: =SUM(U24:U25) -> 39856 | W23: =SUM(S23:U23) -> 114531 | Y23: =SUM(H23,M23,R23,W23) -> 486360
C24: Литвин Андрій | D24: =SUMIFS( тех!$J:$J, тех!$G:$G,'Інтерактивна таблиця'!$C$2, тех!$H:$H,'Інтерактивна таблиця'!D$7, тех!$E:$E,'Інтерактивна таблиця'!$C$3, тех!$B:$B,'Інтерактивна таблиця'!$B$23, тех!$D:$D,'Інтерактивна таблиця'!$C24 ) -> 21304 | E24: =SUMIFS( тех!$J:$J, тех!$G:$G,'Інтерактивна таблиця'!$C$2, тех!$H:$H,'Інтерактивна таблиця'!E$7, тех!$E:$E,'Інтерактивна таблиця'!$C$3, тех!$B:$B,'Інтерактивна таблиця'!$B$23, тех!$D:$D,'Інтерактивна таблиця'!$C24 ) -> 22062 | F24: =SUMIFS( тех!$J:$J, тех!$G:$G,'Інтерактивна таблиця'!$C$2, тех!$H:$H,'Інтерактивна таблиця'!F$7, тех!$E:$E,'Інтерактивна таблиця'!$C$3, тех!$B:$B,'Інтерактивна таблиця'!$B$23, тех!$D:$D,'Інтерактивна таблиця'!$C24 ) -> 19342 | H24: =SUM(D24:F24) -> 62708 | I24: =SUMIFS( тех!$J:$J, тех!$G:$G,'Інтерактивна таблиця'!$C$2, тех!$H:$H,'Інтерактивна таблиця'!I$7, тех!$E:$E,'Інтерактивна таблиця'!$C$3, тех!$B:$B,'Інтерактивна таблиця'!$B$23, тех!$D:$D,'Інтерактивна таблиця'!$C24 ) -> 20326 | J24: =SUMIFS( тех!$J:$J, тех!$G:$G,'Інтерактивна таблиця'!$C$2, тех!$H:$H,'Інтерактивна таблиця'!J$7, тех!$E:$E,'Інтерактивна таблиця'!$C$3, тех!$B:$B,'Інтерактивна таблиця'!$B$23, тех!$D:$D,'Інтерактивна таблиця'!$C24 ) -> 21482 | K24: =SUMIFS( тех!$J:$J, тех!$G:$G,'Інтерактивна таблиця'!$C$2, тех!$H:$H,'Інтерактивна таблиця'!K$7, тех!$E:$E,'Інтерактивна таблиця'!$C$3, тех!$B:$B,'Інтерактивна таблиця'!$B$23, тех!$D:$D,'Інтерактивна таблиця'!$C24 ) -> 18595 | M24: =SUM(I24:K24) -> 60403 | N24: =SUMIFS( тех!$J:$J, тех!$G:$G,'Інтерактивна таблиця'!$C$2, тех!$H:$H,'Інтерактивна таблиця'!N$7, тех!$E:$E,'Інтерактивна таблиця'!$C$3, тех!$B:$B,'Інтерактивна таблиця'!$B$23, тех!$D:$D,'Інтерактивна таблиця'!$C24 ) -> 18103 | O24: =SUMIFS( тех!$J:$J, тех!$G:$G,'Інтерактивна таблиця'!$C$2, тех!$H:$H,'Інтерактивна таблиця'!O$7, тех!$E:$E,'Інтерактивна таблиця'!$C$3, тех!$B:$B,'Інтерактивна таблиця'!$B$23, тех!$D:$D,'Інтерактивна таблиця'!$C24 ) -> 23019 | P24: =SUMIFS( тех!$J:$J, тех!$G:$G,'Інтерактивна таблиця'!$C$2, тех!$H:$H,'Інтерактивна таблиця'!P$7, тех!$E:$E,'Інтерактивна таблиця'!$C$3, тех!$B:$B,'Інтерактивна таблиця'!$B$23, тех!$D:$D,'Інтерактивна таблиця'!$C24 ) -> 19801 | R24: =SUM(N24:P24) -> 60923 | S24: =SUMIFS( тех!$J:$J, тех!$G:$G,'Інтерактивна таблиця'!$C$2, тех!$H:$H,'Інтерактивна таблиця'!S$7, тех!$E:$E,'Інтерактивна таблиця'!$C$3, тех!$B:$B,'Інтерактивна таблиця'!$B$23, тех!$D:$D,'Інтерактивна таблиця'!$C24 ) -> 18132 | T24: =SUMIFS( тех!$J:$J, тех!$G:$G,'Інтерактивна таблиця'!$C$2, тех!$H:$H,'Інтерактивна таблиця'!T$7, тех!$E:$E,'Інтерактивна таблиця'!$C$3, тех!$B:$B,'Інтерактивна таблиця'!$B$23, тех!$D:$D,'Інтерактивна таблиця'!$C24 ) -> 18796 | U24: =SUMIFS( тех!$J:$J, тех!$G:$G,'Інтерактивна таблиця'!$C$2, тех!$H:$H,'Інтерактивна таблиця'!U$7, тех!$E:$E,'Інтерактивна таблиця'!$C$3, тех!$B:$B,'Інтерактивна таблиця'!$B$23, тех!$D:$D,'Інтерактивна таблиця'!$C24 ) -> 20963 | W24: =SUM(S24:U24) -> 57891 | Y24: =SUM(H24,M24,R24,W24) -> 241925 | Z24: =Y24/$Y$10 -> 0.083134682
C25: Нечипоренко Людмила | D25: =SUMIFS( тех!$J:$J, тех!$G:$G,'Інтерактивна таблиця'!$C$2, тех!$H:$H,'Інтерактивна таблиця'!D$7, тех!$E:$E,'Інтерактивна таблиця'!$C$3, тех!$B:$B,'Інтерактивна таблиця'!$B$23, тех!$D:$D,'Інтерактивна таблиця'!$C25 ) -> 19542 | E25: =SUMIFS( тех!$J:$J, тех!$G:$G,'Інтерактивна таблиця'!$C$2, тех!$H:$H,'Інтерактивна таблиця'!E$7, тех!$E:$E,'Інтерактивна таблиця'!$C$3, тех!$B:$B,'Інтерактивна таблиця'!$B$23, тех!$D:$D,'Інтерактивна таблиця'!$C25 ) -> 19412 | F25: =SUMIFS( тех!$J:$J, тех!$G:$G,'Інтерактивна таблиця'!$C$2, тех!$H:$H,'Інтерактивна таблиця'!F$7, тех!$E:$E,'Інтерактивна таблиця'!$C$3, тех!$B:$B,'Інтерактивна таблиця'!$B$23, тех!$D:$D,'Інтерактивна таблиця'!$C25 ) -> 19050 | H25: =SUM(D25:F25) -> 58004 | I25: =SUMIFS( тех!$J:$J, тех!$G:$G,'Інтерактивна таблиця'!$C$2, тех!$H:$H,'Інтерактивна таблиця'!I$7, тех!$E:$E,'Інтерактивна таблиця'!$C$3, тех!$B:$B,'Інтерактивна таблиця'!$B$23, тех!$D:$D,'Інтерактивна таблиця'!$C25 ) -> 22119 | J25: =SUMIFS( тех!$J:$J, тех!$G:$G,'Інтерактивна таблиця'!$C$2, тех!$H:$H,'Інтерактивна таблиця'!J$7, тех!$E:$E,'Інтерактивна таблиця'!$C$3, тех!$B:$B,'Інтерактивна таблиця'!$B$23, тех!$D:$D,'Інтерактивна таблиця'!$C25 ) -> 21835 | K25: =SUMIFS( тех!$J:$J, тех!$G:$G,'Інтерактивна таблиця'!$C$2, тех!$H:$H,'Інтерактивна таблиця'!K$7, тех!$E:$E,'Інтерактивна таблиця'!$C$3, тех!$B:$B,'Інтерактивна таблиця'!$B$23, тех!$D:$D,'Інтерактивна таблиця'!$C25 ) -> 21615 | M25: =SUM(I25:K25) -> 65569 | N25: =SUMIFS( тех!$J:$J, тех!$G:$G,'Інтерактивна таблиця'!$C$2, тех!$H:$H,'Інтерактивна таблиця'!N$7, тех!$E:$E,'Інтерактивна таблиця'!$C$3, тех!$B:$B,'Інтерактивна таблиця'!$B$23, тех!$D:$D,'Інтерактивна таблиця'!$C25 ) -> 21331 | O25: =SUMIFS( тех!$J:$J, тех!$G:$G,'Інтерактивна таблиця'!$C$2, тех!$H:$H,'Інтерактивна таблиця'!O$7, тех!$E:$E,'Інтерактивна таблиця'!$C$3, тех!$B:$B,'Інтерактивна таблиця'!$B$23, тех!$D:$D,'Інтерактивна таблиця'!$C25 ) -> 21228 | P25: =SUMIFS( тех!$J:$J, тех!$G:$G,'Інтерактивна таблиця'!$C$2, тех!$H:$H,'Інтерактивна таблиця'!P$7, тех!$E:$E,'Інтерактивна таблиця'!$C$3, тех!$B:$B,'Інтерактивна таблиця'!$B$23, тех!$D:$D,'Інтерактивна таблиця'!$C25 ) -> 21663 | R25: =SUM(N25:P25) -> 64222 | S25: =SUMIFS( тех!$J:$J, тех!$G:$G,'Інтерактивна таблиця'!$C$2, тех!$H:$H,'Інтерактивна таблиця'!S$7, тех!$E:$E,'Інтерактивна таблиця'!$C$3, тех!$B:$B,'Інтерактивна таблиця'!$B$23, тех!$D:$D,'Інтерактивна таблиця'!$C25 ) -> 18513 | T25: =SUMIFS( тех!$J:$J, тех!$G:$G,'Інтерактивна таблиця'!$C$2, тех!$H:$H,'Інтерактивна таблиця'!T$7, тех!$E:$E,'Інтерактивна таблиця'!$C$3, тех!$B:$B,'Інтерактивна таблиця'!$B$23, тех!$D:$D,'Інтерактивна таблиця'!$C25 ) -> 19234 | U25: =SUMIFS( тех!$J:$J, тех!$G:$G,'Інтерактивна таблиця'!$C$2, тех!$H:$H,'Інтерактивна таблиця'!U$7, тех!$E:$E,'Інтерактивна таблиця'!$C$3, тех!$B:$B,'Інтерактивна таблиця'!$B$23, тех!$D:$D,'Інтерактивна таблиця'!$C25 ) -> 18893 | W25: =SUM(S25:U25) -> 56640 | Y25: =SUM(H25,M25,R25,W25) -> 244435 | Z25: =Y25/$Y$10 -> 0.083997214
B26: Харківська | D26: =SUM(D27:D28) -> 44877 | E26: =SUM(E27:E28) -> 38746 | F26: =SUM(F27:F28) -> 41069 | H26: =SUM(D26:F26) -> 124692 | I26: =SUM(I27:I28) -> 42116 | J26: =SUM(J27:J28) -> 46112 | K26: =SUM(K27:K28) -> 40180 | M26: =SUM(I26:K26) -> 128408 | N26: =SUM(N27:N28) -> 41619 | O26: =SUM(O27:O28) -> 40538 | P26: =SUM(P27:P28) -> 40330 | R26: =SUM(N26:P26) -> 122487 | S26: =SUM(S27:S28) -> 38042 | T26: =SUM(T27:T28) -> 40570 | U26: =SUM(U27:U28) -> 41836 | W26: =SUM(S26:U26) -> 120448 | Y26: =SUM(H26,M26,R26,W26) -> 496035
C27: Мірошник Сергій | D27: =SUMIFS( тех!$J:$J, тех!$G:$G,'Інтерактивна таблиця'!$C$2, тех!$H:$H,'Інтерактивна таблиця'!D$7, тех!$E:$E,'Інтерактивна таблиця'!$C$3, тех!$B:$B,'Інтерактивна таблиця'!$B$26, тех!$D:$D,'Інтерактивна таблиця'!$C27 ) -> 24424 | E27: =SUMIFS( тех!$J:$J, тех!$G:$G,'Інтерактивна таблиця'!$C$2, тех!$H:$H,'Інтерактивна таблиця'!E$7, тех!$E:$E,'Інтерактивна таблиця'!$C$3, тех!$B:$B,'Інтерактивна таблиця'!$B$26, тех!$D:$D,'Інтерактивна таблиця'!$C27 ) -> 21054 | F27: =SUMIFS( тех!$J:$J, тех!$G:$G,'Інтерактивна таблиця'!$C$2, тех!$H:$H,'Інтерактивна таблиця'!F$7, тех!$E:$E,'Інтерактивна таблиця'!$C$3, тех!$B:$B,'Інтерактивна таблиця'!$B$26, тех!$D:$D,'Інтерактивна таблиця'!$C27 ) -> 18987 | H27: =SUM(D27:F27) -> 64465 | I27: =SUMIFS( тех!$J:$J, тех!$G:$G,'Інтерактивна таблиця'!$C$2, тех!$H:$H,'Інтерактивна таблиця'!I$7, тех!$E:$E,'Інтерактивна таблиця'!$C$3, тех!$B:$B,'Інтерактивна таблиця'!$B$26, тех!$D:$D,'Інтерактивна таблиця'!$C27 ) -> 20413 | J27: =SUMIFS( тех!$J:$J, тех!$G:$G,'Інтерактивна таблиця'!$C$2, тех!$H:$H,'Інтерактивна таблиця'!J$7, тех!$E:$E,'Інтерактивна таблиця'!$C$3, тех!$B:$B,'Інтерактивна таблиця'!$B$26, тех!$D:$D,'Інтерактивна таблиця'!$C27 ) -> 22698 | K27: =SUMIFS( тех!$J:$J, тех!$G:$G,'Інтерактивна таблиця'!$C$2, тех!$H:$H,'Інтерактивна таблиця'!K$7, тех!$E:$E,'Інтерактивна таблиця'!$C$3, тех!$B:$B,'Інтерактивна таблиця'!$B$26, тех!$D:$D,'Інтерактивна таблиця'!$C27 ) -> 19992 | M27: =SUM(I27:K27) -> 63103 | N27: =SUMIFS( тех!$J:$J, тех!$G:$G,'Інтерактивна таблиця'!$C$2, тех!$H:$H,'Інтерактивна таблиця'!N$7, тех!$E:$E,'Інтерактивна таблиця'!$C$3, тех!$B:$B,'Інтерактивна таблиця'!$B$26, тех!$D:$D,'Інтерактивна таблиця'!$C27 ) -> 19823 | O27: =SUMIFS( тех!$J:$J, тех!$G:$G,'Інтерактивна таблиця'!$C$2, тех!$H:$H,'Інтерактивна таблиця'!O$7, тех!$E:$E,'Інтерактивна таблиця'!$C$3, тех!$B:$B,'Інтерактивна таблиця'!$B$26, тех!$D:$D,'Інтерактивна таблиця'!$C27 ) -> 19800 | P27: =SUMIFS( тех!$J:$J, тех!$G:$G,'Інтерактивна таблиця'!$C$2, тех!$H:$H,'Інтерактивна таблиця'!P$7, тех!$E:$E,'Інтерактивна таблиця'!$C$3, тех!$B:$B,'Інтерактивна таблиця'!$B$26, тех!$D:$D,'Інтерактивна таблиця'!$C27 ) -> 20201 | R27: =SUM(N27:P27) -> 59824 | S27: =SUMIFS( тех!$J:$J, тех!$G:$G,'Інтерактивна таблиця'!$C$2, тех!$H:$H,'Інтерактивна таблиця'!S$7, тех!$E:$E,'Інтерактивна таблиця'!$C$3, тех!$B:$B,'Інтерактивна таблиця'!$B$26, тех!$D:$D,'Інтерактивна таблиця'!$C27 ) -> 19233 | T27: =SUMIFS( тех!$J:$J, тех!$G:$G,'Інтерактивна таблиця'!$C$2, тех!$H:$H,'Інтерактивна таблиця'!T$7, тех!$E:$E,'Інтерактивна таблиця'!$C$3, тех!$B:$B,'Інтерактивна таблиця'!$B$26, тех!$D:$D,'Інтерактивна таблиця'!$C27 ) -> 19806 | U27: =SUMIFS( тех!$J:$J, тех!$G:$G,'Інтерактивна таблиця'!$C$2, тех!$H:$H,'Інтерактивна таблиця'!U$7, тех!$E:$E,'Інтерактивна таблиця'!$C$3, тех!$B:$B,'Інтерактивна таблиця'!$B$26, тех!$D:$D,'Інтерактивна таблиця'!$C27 ) -> 21903 | W27: =SUM(S27:U27) -> 60942 | Y27: =SUM(H27,M27,R27,W27) -> 248334 | Z27: =Y27/$Y$10 -> 0.085337059
C28: Петров Сергій | D28: =SUMIFS( тех!$J:$J, тех!$G:$G,'Інтерактивна таблиця'!$C$2, тех!$H:$H,'Інтерактивна таблиця'!D$7, тех!$E:$E,'Інтерактивна таблиця'!$C$3, тех!$B:$B,'Інтерактивна таблиця'!$B$26, тех!$D:$D,'Інтерактивна таблиця'!$C28 ) -> 20453 | E28: =SUMIFS( тех!$J:$J, тех!$G:$G,'Інтерактивна таблиця'!$C$2, тех!$H:$H,'Інтерактивна таблиця'!E$7, тех!$E:$E,'Інтерактивна таблиця'!$C$3, тех!$B:$B,'Інтерактивна таблиця'!$B$26, тех!$D:$D,'Інтерактивна таблиця'!$C28 ) -> 17692 | F28: =SUMIFS( тех!$J:$J, тех!$G:$G,'Інтерактивна таблиця'!$C$2, тех!$H:$H,'Інтерактивна таблиця'!F$7, тех!$E:$E,'Інтерактивна таблиця'!$C$3, тех!$B:$B,'Інтерактивна таблиця'!$B$26, тех!$D:$D,'Інтерактивна таблиця'!$C28 ) -> 22082 | H28: =SUM(D28:F28) -> 60227 | I28: =SUMIFS( тех!$J:$J, тех!$G:$G,'Інтерактивна таблиця'!$C$2, тех!$H:$H,'Інтерактивна таблиця'!I$7, тех!$E:$E,'Інтерактивна таблиця'!$C$3, тех!$B:$B,'Інтерактивна таблиця'!$B$26, тех!$D:$D,'Інтерактивна таблиця'!$C28 ) -> 21703 | J28: =SUMIFS( тех!$J:$J, тех!$G:$G,'Інтерактивна таблиця'!$C$2, тех!$H:$H,'Інтерактивна таблиця'!J$7, тех!$E:$E,'Інтерактивна таблиця'!$C$3, тех!$B:$B,'Інтерактивна таблиця'!$B$26, тех!$D:$D,'Інтерактивна таблиця'!$C28 ) -> 23414 | K28: =SUMIFS( тех!$J:$J, тех!$G:$G,'Інтерактивна таблиця'!$C$2, тех!$H:$H,'Інтерактивна таблиця'!K$7, тех!$E:$E,'Інтерактивна таблиця'!$C$3, тех!$B:$B,'Інтерактивна таблиця'!$B$26, тех!$D:$D,'Інтерактивна таблиця'!$C28 ) -> 20188 | M28: =SUM(I28:K28) -> 65305 | N28: =SUMIFS( тех!$J:$J, тех!$G:$G,'Інтерактивна таблиця'!$C$2, тех!$H:$H,'Інтерактивна таблиця'!N$7, тех!$E:$E,'Інтерактивна таблиця'!$C$3, тех!$B:$B,'Інтерактивна таблиця'!$B$26, тех!$D:$D,'Інтерактивна таблиця'!$C28 ) -> 21796 | O28: =SUMIFS( тех!$J:$J, тех!$G:$G,'Інтерактивна таблиця'!$C$2, тех!$H:$H,'Інтерактивна таблиця'!O$7, тех!$E:$E,'Інтерактивна таблиця'!$C$3, тех!$B:$B,'Інтерактивна таблиця'!$B$26, тех!$D:$D,'Інтерактивна таблиця'!$C28 ) -> 20738 | P28: =SUMIFS( тех!$J:$J, тех!$G:$G,'Інтерактивна таблиця'!$C$2, тех!$H:$H,'Інтерактивна таблиця'!P$7, тех!$E:$E,'Інтерактивна таблиця'!$C$3, тех!$B:$B,'Інтерактивна таблиця'!$B$26, тех!$D:$D,'Інтерактивна таблиця'!$C28 ) -> 20129 | R28: =SUM(N28:P28) -> 62663 | S28: =SUMIFS( тех!$J:$J, тех!$G:$G,'Інтерактивна таблиця'!$C$2, тех!$H:$H,'Інтерактивна таблиця'!S$7, тех!$E:$E,'Інтерактивна таблиця'!$C$3, тех!$B:$B,'Інтерактивна таблиця'!$B$26, тех!$D:$D,'Інтерактивна таблиця'!$C28 ) -> 18809 | T28: =SUMIFS( тех!$J:$J, тех!$G:$G,'Інтерактивна таблиця'!$C$2, тех!$H:$H,'Інтерактивна таблиця'!T$7, тех!$E:$E,'Інтерактивна таблиця'!$C$3, тех!$B:$B,'Інтерактивна таблиця'!$B$26, тех!$D:$D,'Інтерактивна таблиця'!$C28 ) -> 20764 | U28: =SUMIFS( тех!$J:$J, тех!$G:$G,'Інтерактивна таблиця'!$C$2, тех!$H:$H,'Інтерактивна таблиця'!U$7, тех!$E:$E,'Інтерактивна таблиця'!$C$3, тех!$B:$B,'Інтерактивна таблиця'!$B$26, тех!$D:$D,'Інтерактивна таблиця'!$C28 ) -> 19933 | W28: =SUM(S28:U28) -> 59506 | Y28: =SUM(H28,M28,R28,W28) -> 247701 | Z28: =Y28/$Y$10 -> 0.085119536

Sheet Зведена таблиця
A1: рік | B1: (кілька елементів)
C3: Квартали | D3: місяці | E3: Значення
C4: 1 квартал | E4: 2 квартал | G4: 3 квартал | I4: 4 квартал
A6: область | B6: менеджер | C6: Відпускні ціни | D6: Частка | E6: Відпускні ціни | F6: Частка | G6: Відпускні ціни | H6: Частка | I6: Відпускні ціни | J6: Частка
A7: Житомирська | B7: Коваль Дмитро | C7: 277357 | D7: 0.083459641 | E7: 290797 | F7: 0.087163721 | G7: 283735 | H7: 0.08602188 | I7: 280014 | J7: 0.083849129
B8: Степанов Денис | C8: 286897 | D8: 0.086330327 | E8: 286453 | F8: 0.085861647 | G8: 279543 | H8: 0.084750963 | I8: 281434 | J8: 0.084274343
A9: Запорізька | B9: Пекар Максим | C9: 237822 | D9: 0.071563143 | E9: 242608 | F9: 0.072719512 | G9: 228166 | H9: 0.069174647 | I9: 230289 | J9: 0.068959167
B10: Сидоров Дмитро | C10: 250080 | D10: 0.075251704 | E10: 238727 | F10: 0.071556218 | G10: 254110 | H10: 0.077040266 | I10: 253488 | J10: 0.075906019
A11: Київська | B11: Іванов Іван | C11: 277685 | D11: 0.083558339 | E11: 288951 | F11: 0.086610399 | G11: 284750 | H11: 0.086329605 | I11: 291712 | J11: 0.087352051
B12: Колесник Анастасія | C12: 292819 | D12: 0.088112319 | E12: 281764 | F12: 0.084456162 | G12: 279755 | H12: 0.084815236 | I12: 286838 | J12: 0.08589255
B13: Савич Андрій | C13: 292111 | D13: 0.087899274 | E13: 283990 | F13: 0.085123385 | G13: 272019 | H13: 0.08246986 | I13: 293223 | J13: 0.087804514
B14: Шевченко Юрій | C14: 288357 | D14: 0.086769656 | E14: 283509 | F14: 0.08497921 | G14: 289154 | H14: 0.087664796 | I14: 288068 | J14: 0.086260869
A15: Одеська | B15: Литвин Андрій | C15: 276605 | D15: 0.083233356 | E15: 282231 | F15: 0.084596141 | G15: 274389 | H15: 0.08318839 | I15: 272700 | J15: 0.08165898
B16: Нечипоренко Людмила | C16: 271075 | D16: 0.081569321 | E16: 290309 | F16: 0.087017447 | G16: 285956 | H16: 0.086695236 | I16: 289000 | J16: 0.086539953
A17: Харківська | B17: Мірошник Сергій | C17: 291097 | D17: 0.087594151 | E17: 279322 | F17: 0.083724195 | G17: 282704 | H17: 0.085709305 | I17: 293344 | J17: 0.087840747
B18: Петров Сергій | C18: 281342 | D18: 0.084658769 | E18: 287555 | F18: 0.086191961 | G18: 284124 | H18: 0.086139816 | I18: 279388 | J18: 0.083661676
A19: Загальний підсумок | C19: 3323247 | D19: 1 | E19: 3336216 | F19: 1 | G19: 3298405 | H19: 1 | I19: 3339498 | J19: 1

Sheet Аркуш2
A3: Рік | B3: Продажі | E3: Рік | F3: Сума з Продаж
A4: 2015 | B4: 4412668 | E4: Одноразовий посуд | F4: 887169
A5: 2016 | B5: 4452783 | E5: Серветки | F5: 979781
A6: 2017 | B6: 4431915 | E6: Зубочистки | F6: 1043087
A7: Підсумок | B7: 13297366 | E7: Засоби для догляду за меблями | F7: 1492620
E8: Мило | F8: 1519990
E9: Засіб для миття посуду | F9: 1636345
A10: Рік | B10: Продажі | E10: Дезодорант | F10: 1783563
A11: Житомирська | B11: 2266230 | E11: Засіб для посудомийних машин | F11: 1784529
A12: Запорізька | B12: 1935290 | E12: Шампунь | F12: 2170282
A13: Київська | B13: 4574705 | E13: Підсумок | F13: 13297366
A14: Одеська | B14: 2242265
A15: Харківська | B15: 2278876
A16: Підсумок | B16: 13297366 | E16: Рік | F16: Продажі
E17: Запоріжжя | F17: 938885
A18: Рік | B18: Продажі | E18: Бердянськ | F18: 996405
A19: Косметика | B19: 5473835 | E19: Одеса | F19: 1105925
A20: Побутова хімія | B20: 4913494 | E20: Житомир | F20: 1131903
A21: Товари для дому | B21: 2910037 | E21: Чугуїв | F21: 1132409
A22: Підсумок | B22: 13297366 | E22: Бердичів | F22: 1134327
E23: Чорноморськ | F23: 1136340
E24: Біла Церква | F24: 1141176
A25: Продажі | E25: Ірпінь | F25: 1141343
A26: 13297366 | E26: Київ | F26: 1143098
E27: Харків | F27: 1146467
E28: Бориспіль | F28: 1149088
A29: Менеджер | B29: Продажі | E29: Підсумок | F29: 13297366
A30: Пекар Максим | B30: 938885
A31: Сидоров Дмитро | B31: 996405
A32: Литвин Андрій | B32: 1105925
A33: Коваль Дмитро | B33: 1131903
A34: Петров Сергій | B34: 1132409
A35: Степанов Денис | B35: 1134327
A36: Нечипоренко Людмила | B36: 1136340
A37: Колесник Анастасія | B37: 1141176
A38: Савич Андрій | B38: 1141343
A39: Іванов Іван | B39: 1143098
A40: Мірошник Сергій | B40: 1146467
A41: Шевченко Юрій | B41: 1149088
A42: Підсумок | B42: 13297366
...

Sheet Dashboard
B1: Дашборд з продажів товарів Home & Beauty

Sheet тех
B1: вихідні дані | C1: Інтеративна табл | O1: таб.1 | P1: для зведеної
B2: область | C2: Місто | D2: менеджер | E2: категорія | F2: найменування | G2: рік | H2: місяць | I2: дата | J2: Продаж | L2: категорія | M2: рік | O2: область | P2: місто | Q2: менеджер | R2: категорія | S2: найменування | T2: рік | U2: місяць | V2: дата | W2: закупівельні ціни | X2: відпускні ціни
B3: Житомирська | C3: Житомир | D3: Коваль Дмитро | E3: Товари для дому | F3: Зубочистки | G3: 2017 | H3: 1 | I3: 42736 | J3: 2350 | L3: Товари для дому | M3: 2015 | O3: Житомирська | P3: Житомир | Q3: Коваль Дмитро | R3: Товари для дому | S3: Зубочистки | T3: 2017 | U3: 1 | V3: 42736 | W3: 2044.5 | X3: 2350
B4: Житомирська | C4: Бердичів | D4: Степанов Денис | E4: Товари для дому | F4: Зубочистки | G4: 2017 | H4: 1 | I4: 42736 | J4: 3154 | L4: Косметика | M4: 2016 | O4: Житомирська | P4: Бердичів | Q4: Степанов Денис | R4: Товари для дому | S4: Зубочистки | T4: 2017 | U4: 1 | V4: 42736 | W4: 2712.44 | X4: 3154
B5: Житомирська | C5: Бердичів | D5: Степанов Денис | E5: Косметика | F5: Дезодорант | G5: 2017 | H5: 1 | I5: 42736 | J5: 4924 | L5: Побутова хімія | M5: 2017 | O5: Житомирська | P5: Бердичів | Q5: Степанов Денис | R5: Косметика | S5: Дезодорант | T5: 2017 | U5: 1 | V5: 42736 | W5: 4431.6 | X5: 4924
B6: Житомирська | C6: Житомир | D6: Коваль Дмитро | E6: Косметика | F6: Дезодорант | G6: 2017 | H6: 1 | I6: 42736 | J6: 3557 | L6: * | M6: <>0 | O6: Житомирська | P6: Житомир | Q6: Коваль Дмитро | R6: Косметика | S6: Дезодорант | T6: 2017 | U6: 1 | V6: 42736 | W6: 3023.45 | X6: 3557
B7: Житомирська | C7: Житомир | D7: Коваль Дмитро | E7: Побутова хімія | F7: Засіб для миття посуду | G7: 2017 | H7: 1 | I7: 42736 | J7: 4195 | O7: Житомирська | P7: Житомир | Q7: Коваль Дмитро | R7: Побутова хімія | S7: Засіб для миття посуду | T7: 2017 | U7: 1 | V7: 42736 | W7: 3607.7 | X7: 4195
B8: Запорізька | C8: Запоріжжя | D8: Пекар Максим | E8: Побутова хімія | F8: Засіб для посудомийних машин | G8: 2017 | H8: 1 | I8: 42736 | J8: 2717 | O8: Запорізька | P8: Запоріжжя | Q8: Пекар Максим | R8: Побутова хімія | S8: Засіб для посудомийних машин | T8: 2017 | U8: 1 | V8: 42736 | W8: 2418.13 | X8: 2717
B9: Київська | C9: Бориспіль | D9: Шевченко Юрій | E9: Побутова хімія | F9: Засоби для догляду за меблями | G9: 2017 | H9: 1 | I9: 42736 | J9: 2942 | O9: Київська | P9: Бориспіль | Q9: Шевченко Юрій | R9: Побутова хімія | S9: Засоби для догляду за меблями | T9: 2017 | U9: 1 | V9: 42736 | W9: 2559.54 | X9: 2942
B10: Одеська | C10: Одеса | D10: Литвин Андрій | E10: Товари для дому | F10: Серветки | G10: 2017 | H10: 1 | I10: 42736 | J10: 2288 | O10: Одеська | P10: Одеса | Q10: Литвин Андрій | R10: Товари для дому | S10: Серветки | T10: 2017 | U10: 1 | V10: 42736 | W10: 2082.08 | X10: 2288
B11: Харківська | C11: Харків | D11: Мірошник Сергій | E11: Товари для дому | F11: Зубочистки | G11: 2017 | H11: 1 | I11: 42736 | J11: 2652 | O11: Харківська | P11: Харків | Q11: Мірошник Сергій | R11: Товари для дому | S11: Зубочистки | T11: 2017 | U11: 1 | V11: 42736 | W11: 2386.8 | X11: 2652
B12: Житомирська | C12: Бердичів | D12: Степанов Денис | E12: Товари для дому | F12: Одноразовий посуд | G12: 2017 | H12: 1 | I12: 42736 | J12: 2310 | O12: Житомирська | P12: Бердичів | Q12: Степанов Денис | R12: Товари для дому | S12: Одноразовий посуд | T12: 2017 | U12: 1 | V12: 42736 | W12: 1963.5 | X12: 2310
B13: Запорізька | C13: Бердянськ | D13: Сидоров Дмитро | E13: Косметика | F13: Шампунь | G13: 2017 | H13: 1 | I13: 42736 | J13: 5391 | O13: Запорізька | P13: Бердянськ | Q13: Сидоров Дмитро | R13: Косметика | S13: Шампунь | T13: 2017 | U13: 1 | V13: 42736 | W13: 5013.63 | X13: 5391
B14: Київська | C14: Біла Церква | D14: Колесник Анастасія | E14: Косметика | F14: Дезодорант | G14: 2017 | H14: 1 | I14: 42736 | J14: 3591 | O14: Київська | P14: Біла Церква | Q14: Колесник Анастасія | R14: Косметика | S14: Дезодорант | T14: 2017 | U14: 1 | V14: 42736 | W14: 3375.54 | X14: 3591
B15: Одеська | C15: Чорноморськ | D15: Нечипоренко Людмила | E15: Косметика | F15: Мило | G15: 2017 | H15: 1 | I15: 42736 | J15: 3813 | O15: Одеська | P15: Чорноморськ | Q15: Нечипоренко Людмила | R15: Косметика | S15: Мило | T15: 2017 | U15: 1 | V15: 42736 | W15: 3279.18 | X15: 3813
B16: Харківська | C16: Чугуїв | D16: Петров Сергій | E16: Побутова хімія | F16: Засіб для миття посуду | G16: 2017 | H16: 1 | I16: 42736 | J16: 3905 | O16: Харківська | P16: Чугуїв | Q16: Петров Сергій | R16: Побутова хімія | S16: Засіб для миття посуду | T16: 2017 | U16: 1 | V16: 42736 | W16: 3631.65 | X16: 3905
B17: Житомирська | C17: Житомир | D17: Коваль Дмитро | E17: Побутова хімія | F17: Засіб для посудомийних машин | G17: 2017 | H17: 1 | I17: 42736 | J17: 3482 | O17: Житомирська | P17: Житомир | Q17: Коваль Дмитро | R17: Побутова хімія | S17: Засіб для посудомийних машин | T17: 2017 | U17: 1 | V17: 42736 | W17: 2994.52 | X17: 3482
B18: Запорізька | C18: Запоріжжя | D18: Пекар Максим | E18: Побутова хімія | F18: Засоби для догляду за меблями | G18: 2017 | H18: 1 | I18: 42736 | J18: 3358 | O18: Запорізька | P18: Запоріжжя | Q18: Пекар Максим | R18: Побутова хімія | S18: Засоби для догляду за меблями | T18: 2017 | U18: 1 | V18: 42736 | W18: 3055.78 | X18: 3358
... B3818: Київська | C3818: Київ | D3818: Іванов Іван | E3818: Товари для дому | F3818: Зубочистки | G3818: 2015 | H3818: 12 | I3818: 42339 | J3818: 2918 | O3818: Київська | P3818: Київ | Q3818: Іванов Іван | R3818: Товари для дому | S3818: Зубочистки | T3818: 2015 | U3818: 12 | V3818: 42339 | W3818: 2742.92 | X3818: 2918
